<?xml version="1.0"?>
<robot name="gazebo1" xmlns:xacro="http://ros.org/wiki/xacro">

  <!-- _______________ Ordforklaringer _______________ -->

  <!--  E = East, W = West, N = North, S = South    (Sett fra roboten sin side) -->
  <!--  L = Lengde, B = Bredde, H = Hoyde                                       -->
  <!--  D = Down, U = Up                            (Sett fra roboten sin side) -->



  <!-- _____________________________________________________________ -->
  <!-- ________________________ DEKLARERING ________________________ -->
	<!-- _____________________________________________________________ -->




	<!-- _______________ Variabler _______________ -->

  <xacro:property name="rpy_default" value="0 0 0" />
	<xacro:property name="xyz_default" value="0 0 0" />
	<xacro:property name="baseL" value="1.8" />
  <xacro:property name="baseB" value="0.76" />
  <xacro:property name="baseH" value="0.05" />
  <xacro:property name="pi" value="3.1415" />
  <xacro:property name="veggB" value="0.1" />
  <xacro:property name="veggH" value="0.15" />
  <xacro:property name="sylinderHolderDim" value="0.03" />
  <xacro:property name="sylinderR" value="0.015" />
  <xacro:property name="sliderR" value="0.02" />
  <xacro:property name="sliderL" value="0.03" />
  <xacro:property name="racketR" value="0.05" />
  <xacro:property name="racketL" value="0.03" />
  <xacro:property name="slider1Velocity" value="4" />
  <xacro:property name="slider2Velocity" value="4" />
 
  <xacro:macro name="default_inertial" params="mass">
    <inertial>
      <mass value="${mass}" />
      <inertia ixx="0.00035" ixy="0.0" ixz="0.0" iyy="0.00035" iyz="0.0" izz="0.0004" />
      <origin rpy="${pi/2} 0 0" xyz="0 ${sliderL/2} 0"/>
    </inertial>
  </xacro:macro>


	<!-- _______________ Kube genererings funksjon _______________ -->
  
  <xacro:macro name="kube" params ="navn b l h xyz:={xyz_default} rpy:=${rpy_default} mass:=10 farge:=Gazebo/White">
    <link name="${navn}">
      <visual>
        <geometry>
          <box size="${b} ${l} ${h}"/>
        </geometry>
        <origin rpy="${rpy}" xyz="${xyz}"/>
      </visual>
      <collision>
        <geometry>
          <box size="${b} ${l} ${h}"/>
        </geometry>
        <origin rpy="${rpy}" xyz="${xyz}"/>
      </collision>
        <inertial>
        	<mass value="${mass}" />
        	<inertia ixx="${mass*(l*l+h*h)/12}" ixy="0.0" ixz="0.0" iyy="${mass*(b*b+h*h)/12}" iyz="0.0" izz="${mass*(b*b+l*l)/12}" />
        	<origin rpy="${rpy}" xyz="${xyz}"/>
        </inertial>
    </link>

    <gazebo reference="${navn}">
        <material>${farge}</material>
    </gazebo>
  </xacro:macro> 
  

  <!-- _______________ Vegg genererings funksjon _______________ -->

<xacro:macro name="kube2" params ="navn b l h xyz:={xyz_default} rpy:=${rpy_default} mass:=10 farge:=Gazebo/White">
    <link name="${navn}">
      <visual>
        <geometry>
          <box size="${b} ${l} ${h}"/>
        </geometry>
        <origin rpy="${rpy}" xyz="${xyz}"/>
      </visual>
      <collision>
        <geometry>
          <box size="${b} ${l} ${h}"/>
        </geometry>
        <origin rpy="${rpy}" xyz="${xyz}"/>
        <surface>
          <bounce restitution_coefficient="0.5" threshold="0"/>
        </surface>
        <contact>
          <ode>
             <max_vel>20</max_vel>
          </ode>
        </contact>
      </collision>
        <inertial>
        	<mass value="${mass}" />
        	<inertia ixx="${mass*(l*l+h*h)/12}" ixy="0.0" ixz="0.0" iyy="${mass*(b*b+h*h)/12}" iyz="0.0" izz="${mass*(b*b+l*l)/12}" />
        	<origin rpy="${rpy}" xyz="${xyz}"/>
        </inertial>
    </link>

    <gazebo reference="${navn}">
      <mu1 value="100.0" />
      <mu2 value="100.0" />
      **<maxVel value="20.0"/>**
      <kp value="100000.0" />
      <kd value="0.1" />
      <turnGravityOff>false</turnGravityOff>
      <material>${farge}</material>
    </gazebo>
  </xacro:macro> 


  <!-- _______________ Sylinder genererings funksjon _______________ -->

	<xacro:macro name="sylinder" params ="navn r l xyz:={xyz_default} rpy:=${rpy_default} mass:=10 farge:=Gazebo/White">
    <link name="${navn}">
      <visual>
        <geometry>
          <cylinder radius="${r}" length="${l}"/>
        </geometry>
        <origin rpy="${rpy}" xyz="${xyz}"/>
      </visual>
      <collision>
        <geometry>
          <cylinder radius="${r}" length="${l}"/>
        </geometry>
        <origin rpy="${rpy}" xyz="${xyz}"/>
        <surface>
          <bounce restitution_coefficient="0.5" threshold="0"/>
        </surface>
        <contact>
          <ode>
             <max_vel>20</max_vel>
          </ode>
        </contact>
      </collision>
        <inertial>
        	<mass value="${mass}" />
        	<inertia ixx="${mass*(3*r*r+l*l)/6}" ixy="0.0" ixz="0.0" iyy="${mass*(3*r*r+l*l)/6}" iyz="0.0" izz="${mass*r*r}" />
          <origin rpy="${rpy}" xyz="${xyz}"/>

        </inertial>
    </link>

    <gazebo reference="${navn}">
      <mu1 value="100.0" />
      <mu2 value="100.0" />
      **<maxVel value="20.0"/>**
      <kp value="10000.0" />
      <kd value="0.1" />
      <turnGravityOff>false</turnGravityOff>
      <material>${farge}</material>
    </gazebo>
  </xacro:macro> 



  <!-- ______________________________________________________________ -->
  <!-- ___________________________ MODELL ___________________________ -->
	<!-- ______________________________________________________________ -->


	<!-- _______________ Ground base _______________ -->
  <!-- ___________________________________________ -->

  <link name="dummy">
  </link>

  <xacro:kube2 navn="base_link" b="${baseB}" l="${baseL}" h="${baseH}" xyz="0 0 ${baseH/2}" mass="20" />

  <joint name="dummy_joint" type="fixed">
		<parent link="dummy"/>
		<child link="base_link"/>
		<origin xyz="0 0 0" />
	</joint>


	<!-- _______________ Vegger _______________ -->
  <!-- ______________________________________ -->

  <xacro:kube2 navn="veggE" b="${veggB}" l="${baseL}" h="${veggH}" xyz="${veggB/2} 0 ${veggH/2}" mass="4" farge="Gazebo/Wood"/>
  <xacro:kube2 navn="veggW" b="${veggB}" l="${baseL}" h="${veggH}" xyz="${-veggB/2} 0 ${veggH/2}" mass="4" farge="Gazebo/Wood" />
  <xacro:kube2 navn="veggN" b="${baseB + 2*veggB}" l="${veggB}" h="${veggH}" xyz="0 ${veggB/2} ${veggH/2}" mass="4" farge="Gazebo/Wood"/>
  <xacro:kube2 navn="veggS" b="${baseB + 2*veggB}" l="${veggB}" h="${veggH}" xyz="0 ${-veggB/2} ${veggH/2}" mass="4" farge="Gazebo/Wood"/>

  <joint name="veggE_base" type="fixed">
		<parent link="base_link"/>
		<child link="veggE"/>
		<origin xyz="${baseB/2} 0 0" />
	</joint>

  <joint name="veggW_base" type="fixed">
		<parent link="base_link"/>
		<child link="veggW"/>
		<origin xyz="${-baseB/2} 0 0" />
	</joint>

  <joint name="veggN_base" type="fixed">
		<parent link="base_link"/>
		<child link="veggN"/>
		<origin xyz="0 ${baseL/2} 0" />
	</joint>

  <joint name="veggS_base" type="fixed">
		<parent link="base_link"/>
		<child link="veggS"/>
		<origin xyz="0 ${-baseL/2} 0" />
	</joint>

  <!-- _______________ Sylinder og Sylinderholder _______________ -->
  <!-- __________________________________________________________ -->

  <xacro:kube2 navn="sylinderHolderED" b="${sylinderHolderDim}" l="${sylinderHolderDim/2}" h="${sylinderHolderDim}" 
              xyz="0 ${sylinderHolderDim/4} ${sylinderHolderDim/2}" mass="0.5" farge ="Gazebo/Grey"/>

  <xacro:kube2 navn="sylinderHolderEU" b="${sylinderHolderDim}" l="${sylinderHolderDim/2}" h="${sylinderHolderDim}" 
              xyz="0 ${sylinderHolderDim/4} ${sylinderHolderDim/2}" mass="0.5" farge ="Gazebo/Grey"/>

  <xacro:kube2 navn="sylinderHolderWU" b="${sylinderHolderDim}" l="${sylinderHolderDim/2}" h="${sylinderHolderDim}" 
              xyz="0 ${sylinderHolderDim/4} ${sylinderHolderDim/2}" mass="0.5" farge ="Gazebo/Grey"/>

  <xacro:kube2 navn="sylinderHolderWD" b="${sylinderHolderDim}" l="${sylinderHolderDim/2}" h="${sylinderHolderDim}" 
              xyz="0 ${sylinderHolderDim/4} ${sylinderHolderDim/2}" mass="0.5" farge ="Gazebo/Grey" />

  
  <joint name="sylinderHolderED_VeggE" type="fixed">
    <parent link="veggE"/>
    <child link="sylinderHolderED"/>
    <origin xyz="${veggB/2} ${-baseL/2} ${veggH}"/>
  </joint>

  <joint name="sylinderHolderEU_VeggE" type="fixed">
    <parent link="veggE"/>
    <child link="sylinderHolderEU"/>
    <origin xyz="${veggB/2} 0 ${veggH}"/>
  </joint>

  <joint name="sylinderHolderWU_VeggE" type="fixed">
    <parent link="veggW"/>
    <child link="sylinderHolderWU"/>
    <origin xyz="${-veggB/2} 0 ${veggH}"/>
  </joint>

  <joint name="sylinderHolderWD_VeggE" type="fixed">
    <parent link="veggW"/>
    <child link="sylinderHolderWD"/>
    <origin xyz="${-veggB/2} ${-baseL/2} ${veggH}"/>
  </joint>



  <xacro:sylinder navn="sylinderE" r="${sylinderR}" l="${baseL/2 + sylinderHolderDim/2}" 
                  xyz="0 ${(baseL/2 + sylinderHolderDim/2)/2} 0" rpy="${pi/2} 0 0" mass="1" farge ="Gazebo/Grey"/>

  <xacro:sylinder navn="sylinderW" r="${sylinderR}" l="${baseL/2 + sylinderHolderDim/2}" 
                  xyz="0 ${(baseL/2 + sylinderHolderDim/2)/2} 0" rpy="${pi/2} 0 0" mass="1" farge ="Gazebo/Grey"/>

  
  <joint name="sylinderHolderED_sylinderE" type="fixed">
    <parent link="sylinderHolderED"/>
    <child link="sylinderE"/>
    <origin xyz="0 0 ${sylinderHolderDim}"/>
  </joint>


  <joint name="sylinderHolderWD_sylinderW" type="fixed">
    <parent link="sylinderHolderWD"/>
    <child link="sylinderW"/>
    <origin xyz="0 0 ${sylinderHolderDim}"/>
  </joint>



  <!-- _______________ Slidere _______________ -->
  <!-- _______________________________________ -->

  <xacro:sylinder navn="slider1" r="${sliderR}" l="${sliderL}" 
                  xyz="0 ${sliderL/2} 0" rpy="${pi/2} 0 0" mass="1" farge ="Gazebo/Red"/>

  
  <joint name="slider1_control" type="prismatic">
    <parent link="sylinderW"/>
    <child link="slider1"/>
    <limit effort="1000.0" lower="0" upper="${baseL/2-sylinderHolderDim-racketR}" velocity="${slider1Velocity}"/>
    <origin xyz="0 ${racketR} 0"/>
    <axis xyz="0 1 0"/>
    <limit effort="30" velocity="${slider1Velocity}"/>
    <dynamics damping="1" friction="1"/>
  </joint>


  <xacro:sylinder navn="sylinderMiddle" r="${sylinderR}" l="${baseB + veggB-2*sylinderR}" 
                  xyz="${(baseB + veggB-2*sylinderR)/2} 0 0" rpy="0 ${pi/2} 0" mass="0.1" farge ="Gazebo/Grey"/>


  <joint name="sylinderMiddle_slider1" type="fixed">
    <parent link="slider1"/>
    <child link="sylinderMiddle"/>
    <origin xyz="${sylinderR} ${sliderL/2} 0"/>
  </joint>



  <xacro:sylinder navn="slider2" r="${sliderR}" l="${sliderL}" 
                  xyz="0 ${sliderL/2} 0" rpy="${pi/2} 0 0" mass="0.1" farge ="Gazebo/Red"/>


  <joint name="slider2_sylinderMiddle" type="fixed">
    <parent link="sylinderMiddle"/>
    <child link="slider2"/>
    <origin xyz="${(baseB + veggB-2*sylinderR) + sylinderR} ${-sliderL/2} 0"/>
  </joint>



  <xacro:sylinder navn="sliderMiddle" r="${sliderR}" l="${sliderL}" 
                  xyz="${sliderL/2} 0 0" rpy="0 ${pi/2} 0" mass="0.1" farge ="Gazebo/Red"/>


  <joint name="slider2_control" type="prismatic">
    <parent link="sylinderMiddle"/>
    <child link="sliderMiddle"/>
    <limit effort="1000.0" lower="0" upper="${baseB - racketR*2}" velocity="${slider2Velocity}"/>
    <origin xyz="${(veggB/2-sylinderR+racketR-sliderL/2)}  0  0"/>
    <axis xyz="1 0 0"/>
    <dynamics damping="0.1" friction="0.1"/>
  </joint>


 


  <!-- _______________ Robot racket _______________ -->
  <!-- ____________________________________________ -->


  <xacro:sylinder navn="racketHolder" r="${sylinderR}" l="${veggH+sylinderHolderDim-baseH-sylinderR}" 
                  xyz="0 0 ${-(veggH+sylinderHolderDim-baseH-sylinderR)/2}" rpy="0 0 0" mass="0.1" farge ="Gazebo/Grey"/>


  <joint name="sliderMiddle_racketHolder" type="fixed">
    <parent link="sliderMiddle"/>
    <child link="racketHolder"/>
    <origin xyz="${sliderL/2} 0 ${-sylinderR}"/>
  </joint>


  <xacro:sylinder navn="racket" r="${racketR}" l="${racketL}" farge="Gazebo/Black"
                  xyz="0 0 ${racketL/2}" rpy="0 0 0" mass="0.1"/>

  
  <joint name="racketHolder_racket" type="fixed">
    <parent link="racketHolder"/>
    <child link="racket"/>
    <origin xyz="0 0 ${-(veggH+sylinderHolderDim-baseH-sylinderR)} "/>
  </joint>




  <!-- _______________ Styring av prismatiske ledd _______________ -->
  <!-- ___________________________________________________________ -->

  


  <!-- __ EffortJointInterface __ -->

    <transmission name="slider1_control_trans" type="transmission_interface/SimpleTransmission">
    <type>transmission_interface/SimpleTransmission</type>
    <actuator name="slider1_control_motor">
      <hardwareInterface>hardware_interface/EffortJointInterface</hardwareInterface>
      <mechanicalReduction>1</mechanicalReduction>
    </actuator>
    <joint name="slider1_control">
      <hardwareInterface>hardware_interface/EffortJointInterface</hardwareInterface>
    </joint>
  </transmission>

    <transmission name="slider2_control_trans" type="transmission_interface/SimpleTransmission">
    <type>transmission_interface/SimpleTransmission</type>
    <actuator name="slider2_control_motor">
      <hardwareInterface>hardware_interface/EffortJointInterface</hardwareInterface>
      <mechanicalReduction>1</mechanicalReduction>
    </actuator>
    <joint name="slider2_control">
      <hardwareInterface>hardware_interface/EffortJointInterface</hardwareInterface>
    </joint>
  </transmission>



  <!-- ______________________ Plugin __________________________ -->
  <!-- ________________________________________________________ -->

  <gazebo>
    <plugin name="gazebo_ros_control" filename="libgazebo_ros_control.so">
      <robotNamespace>/</robotNamespace>
    </plugin>
  </gazebo>

</robot>